No CUDA runtime is found, using CUDA_HOME='/usr/local/cuda'
2025-03-27 11:28:51,779 - launch.py - accelerate.commands.launch - WARNING - The following values were not passed to `accelerate launch` and had defaults used instead:
	`--num_cpu_threads_per_process` was set to `2` to improve out-of-box performance when training on CPUs
To avoid this warning pass in values for each of the problematic parameters or run `accelerate config`.
/opt/conda/bin/python: can't open file '/home/salvadordeharoo/IDL/practica1/scripts_python/mobileViT-inf_params_cpu.py': [Errno 2] No such file or directory
Traceback (most recent call last):
  File "/opt/conda/bin/accelerate", line 8, in <module>
    sys.exit(main())
             ^^^^^^
  File "/opt/conda/lib/python3.12/site-packages/accelerate/commands/accelerate_cli.py", line 48, in main
    args.func(args)
  File "/opt/conda/lib/python3.12/site-packages/accelerate/commands/launch.py", line 1194, in launch_command
    simple_launcher(args)
  File "/opt/conda/lib/python3.12/site-packages/accelerate/commands/launch.py", line 780, in simple_launcher
    raise subprocess.CalledProcessError(returncode=process.returncode, cmd=cmd)
subprocess.CalledProcessError: Command '['/opt/conda/bin/python', '/home/salvadordeharoo/IDL/practica1/scripts_python/mobileViT-inf_params_cpu.py', '--batch_size', '16', '--img_size', '256']' returned non-zero exit status 2.

real	0m12.990s
user	0m8.480s
sys	0m2.643s
